Workbook

Sheet التقرير
A1: ="تقرير تحقيق المناديب – حتى "&TEXT(الإعدادات!$B$2,"dd/mm/yyyy") -> تقرير تحقيق المناديب – حتى 17/10/2026
A2: ="التارجت الشهري: هنجرستيشن "&الإعدادات!$B$19&" – كيتا "&الإعدادات!$B$20&" – نينجا "&الإعدادات!$B$21&" طلب | الهدف اليومي = التارجت ÷ "&الإعدادات!$B$4&" | الهدف = اليومي × أيام الاحتساب (أيام فيها طلبات)" -> التارجت الشهري: هنجرستيشن 450 – كيتا 450 – نينجا 360 طلب | الهدف اليومي = التارجت ÷ 30 | الهدف = اليومي × أيام الاحتساب (أيام فيها طلبات)
A3: عدد المناديب
B4: إجمالي المناديب | C4: على الكفالة | D4: فري لانسر | E4: يوزرات | L4: =HYPERLINK("#'الإدخال اليومي'!A"&(5+COUNTA('الإدخال اليومي'!$B$5:$B$234)),"➕ إضافة مندوب جديد (اضغط هنا)") -> ➕ إضافة مندوب جديد (اضغط هنا)
B5: =SUMIFS($R$31:$R$260,$S$31:$S$260,"يعمل") -> 167 | C5: =SUMIFS($R$31:$R$260,$E$31:$E$260,"كفالة",$S$31:$S$260,"يعمل") -> 98 | D5: =SUMIFS($R$31:$R$260,$E$31:$E$260,"فري لانسر",$S$31:$S$260,"يعمل") -> 56 | E5: =SUMIFS($R$31:$R$260,$E$31:$E$260,"يوزرات",$S$31:$S$260,"يعمل") -> 13
A7: توزيع المناديب العاملين على المشاريع والجهات
B8: الإجمالي | C8: امازون | F8: كيتا | I8: هنجرستيشن | L8: نينجا
C9: كفالة | D9: فري لانسر | E9: يوزرات | F9: كفالة | G9: فري لانسر | H9: يوزرات | I9: كفالة | J9: فري لانسر | K9: يوزرات | L9: كفالة | M9: فري لانسر | N9: يوزرات
B10: =SUM(C10:N10) -> 167 | C10: =SUMIFS($R$31:$R$260,$C$31:$C$260,"امازون",$E$31:$E$260,"كفالة",$S$31:$S$260,"يعمل") -> 48 | D10: =SUMIFS($R$31:$R$260,$C$31:$C$260,"امازون",$E$31:$E$260,"فري لانسر",$S$31:$S$260,"يعمل") -> 2 | E10: =SUMIFS($R$31:$R$260,$C$31:$C$260,"امازون",$E$31:$E$260,"يوزرات",$S$31:$S$260,"يعمل") -> 0 | F10: =SUMIFS($R$31:$R$260,$C$31:$C$260,"كيتا",$E$31:$E$260,"كفالة",$S$31:$S$260,"يعمل") -> 28 | G10: =SUMIFS($R$31:$R$260,$C$31:$C$260,"كيتا",$E$31:$E$260,"فري لانسر",$S$31:$S$260,"يعمل") -> 46 | H10: =SUMIFS($R$31:$R$260,$C$31:$C$260,"كيتا",$E$31:$E$260,"يوزرات",$S$31:$S$260,"يعمل") -> 0 | I10: =SUMIFS($R$31:$R$260,$C$31:$C$260,"هنجرستيشن",$E$31:$E$260,"كفالة",$S$31:$S$260,"يعمل") -> 22 | J10: =SUMIFS($R$31:$R$260,$C$31:$C$260,"هنجرستيشن",$E$31:$E$260,"فري لانسر",$S$31:$S$260,"يعمل") -> 4 | K10: =SUMIFS($R$31:$R$260,$C$31:$C$260,"هنجرستيشن",$E$31:$E$260,"يوزرات",$S$31:$S$260,"يعمل") -> 0 | L10: =SUMIFS($R$31:$R$260,$C$31:$C$260,"نينجا",$E$31:$E$260,"كفالة",$S$31:$S$260,"يعمل") -> 0 | M10: =SUMIFS($R$31:$R$260,$C$31:$C$260,"نينجا",$E$31:$E$260,"فري لانسر",$S$31:$S$260,"يعمل") -> 4 | N10: =SUMIFS($R$31:$R$260,$C$31:$C$260,"نينجا",$E$31:$E$260,"يوزرات",$S$31:$S$260,"يعمل") -> 13
A12: ملخص التحقيق حسب المشرف والمشروع
B13: المشرف | C13: المشروع | D13: عدد المناديب | E13: حقق | F13: قريب | G13: بعيد | H13: نسبة التحقيق | I13: شحنات امازون
B14: محمود خطاب | C14: هنجرستيشن | D14: =IF(AND($B14="",$C14=""),"",SUMIFS($R$31:$R$260,$H$31:$H$260,IF($B14="","*",$B14),$C$31:$C$260,IF($C14="","*",$C14),$S$31:$S$260,"يعمل")) -> 26 | E14: =IF(AND($B14="",$C14=""),"",SUMIFS($R$31:$R$260,$H$31:$H$260,IF($B14="","*",$B14),$C$31:$C$260,IF($C14="","*",$C14),$P$31:$P$260,"حقق")) -> 14 | F14: =IF(AND($B14="",$C14=""),"",SUMIFS($R$31:$R$260,$H$31:$H$260,IF($B14="","*",$B14),$C$31:$C$260,IF($C14="","*",$C14),$P$31:$P$260,"قريب")) -> 4 | G14: =IF(AND($B14="",$C14=""),"",SUMIFS($R$31:$R$260,$H$31:$H$260,IF($B14="","*",$B14),$C$31:$C$260,IF($C14="","*",$C14),$P$31:$P$260,"بعيد")) -> 8 | H14: =IF(AND($B14="",$C14=""),"",IF(E14+F14+G14=0,0,E14/(E14+F14+G14))) -> 0.53846154 | I14: =IF(AND($B14="",$C14=""),"",SUMIFS($G$31:$G$260,$H$31:$H$260,IF($B14="","*",$B14),$C$31:$C$260,IF($C14="","*",$C14),$R$31:$R$260,1)) -> 0
B15: محمود خطاب | C15: كيتا | D15: =IF(AND($B15="",$C15=""),"",SUMIFS($R$31:$R$260,$H$31:$H$260,IF($B15="","*",$B15),$C$31:$C$260,IF($C15="","*",$C15),$S$31:$S$260,"يعمل")) -> 26 | E15: =IF(AND($B15="",$C15=""),"",SUMIFS($R$31:$R$260,$H$31:$H$260,IF($B15="","*",$B15),$C$31:$C$260,IF($C15="","*",$C15),$P$31:$P$260,"حقق")) -> 23 | F15: =IF(AND($B15="",$C15=""),"",SUMIFS($R$31:$R$260,$H$31:$H$260,IF($B15="","*",$B15),$C$31:$C$260,IF($C15="","*",$C15),$P$31:$P$260,"قريب")) -> 2 | G15: =IF(AND($B15="",$C15=""),"",SUMIFS($R$31:$R$260,$H$31:$H$260,IF($B15="","*",$B15),$C$31:$C$260,IF($C15="","*",$C15),$P$31:$P$260,"بعيد")) -> 1 | H15: =IF(AND($B15="",$C15=""),"",IF(E15+F15+G15=0,0,E15/(E15+F15+G15))) -> 0.88461538 | I15: =IF(AND($B15="",$C15=""),"",SUMIFS($G$31:$G$260,$H$31:$H$260,IF($B15="","*",$B15),$C$31:$C$260,IF($C15="","*",$C15),$R$31:$R$260,1)) -> 0
B16: خالد عباس | C16: كيتا | D16: =IF(AND($B16="",$C16=""),"",SUMIFS($R$31:$R$260,$H$31:$H$260,IF($B16="","*",$B16),$C$31:$C$260,IF($C16="","*",$C16),$S$31:$S$260,"يعمل")) -> 47 | E16: =IF(AND($B16="",$C16=""),"",SUMIFS($R$31:$R$260,$H$31:$H$260,IF($B16="","*",$B16),$C$31:$C$260,IF($C16="","*",$C16),$P$31:$P$260,"حقق")) -> 32 | F16: =IF(AND($B16="",$C16=""),"",SUMIFS($R$31:$R$260,$H$31:$H$260,IF($B16="","*",$B16),$C$31:$C$260,IF($C16="","*",$C16),$P$31:$P$260,"قريب")) -> 6 | G16: =IF(AND($B16="",$C16=""),"",SUMIFS($R$31:$R$260,$H$31:$H$260,IF($B16="","*",$B16),$C$31:$C$260,IF($C16="","*",$C16),$P$31:$P$260,"بعيد")) -> 9 | H16: =IF(AND($B16="",$C16=""),"",IF(E16+F16+G16=0,0,E16/(E16+F16+G16))) -> 0.68085106 | I16: =IF(AND($B16="",$C16=""),"",SUMIFS($G$31:$G$260,$H$31:$H$260,IF($B16="","*",$B16),$C$31:$C$260,IF($C16="","*",$C16),$R$31:$R$260,1)) -> 0
B17: خالد عباس | C17: نينجا | D17: =IF(AND($B17="",$C17=""),"",SUMIFS($R$31:$R$260,$H$31:$H$260,IF($B17="","*",$B17),$C$31:$C$260,IF($C17="","*",$C17),$S$31:$S$260,"يعمل")) -> 17 | E17: =IF(AND($B17="",$C17=""),"",SUMIFS($R$31:$R$260,$H$31:$H$260,IF($B17="","*",$B17),$C$31:$C$260,IF($C17="","*",$C17),$P$31:$P$260,"حقق")) -> 5 | F17: =IF(AND($B17="",$C17=""),"",SUMIFS($R$31:$R$260,$H$31:$H$260,IF($B17="","*",$B17),$C$31:$C$260,IF($C17="","*",$C17),$P$31:$P$260,"قريب")) -> 3 | G17: =IF(AND($B17="",$C17=""),"",SUMIFS($R$31:$R$260,$H$31:$H$260,IF($B17="","*",$B17),$C$31:$C$260,IF($C17="","*",$C17),$P$31:$P$260,"بعيد")) -> 9 | H17: =IF(AND($B17="",$C17=""),"",IF(E17+F17+G17=0,0,E17/(E17+F17+G17))) -> 0.29411765 | I17: =IF(AND($B17="",$C17=""),"",SUMIFS($G$31:$G$260,$H$31:$H$260,IF($B17="","*",$B17),$C$31:$C$260,IF($C17="","*",$C17),$R$31:$R$260,1)) -> 0
B18: عبدالرحمن رحومة | C18: امازون | D18: =IF(AND($B18="",$C18=""),"",SUMIFS($R$31:$R$260,$H$31:$H$260,IF($B18="","*",$B18),$C$31:$C$260,IF($C18="","*",$C18),$S$31:$S$260,"يعمل")) -> 50 | E18: =IF(AND($B18="",$C18=""),"",SUMIFS($R$31:$R$260,$H$31:$H$260,IF($B18="","*",$B18),$C$31:$C$260,IF($C18="","*",$C18),$P$31:$P$260,"حقق")) -> 0 | F18: =IF(AND($B18="",$C18=""),"",SUMIFS($R$31:$R$260,$H$31:$H$260,IF($B18="","*",$B18),$C$31:$C$260,IF($C18="","*",$C18),$P$31:$P$260,"قريب")) -> 0 | G18: =IF(AND($B18="",$C18=""),"",SUMIFS($R$31:$R$260,$H$31:$H$260,IF($B18="","*",$B18),$C$31:$C$260,IF($C18="","*",$C18),$P$31:$P$260,"بعيد")) -> 0 | H18: =IF(AND($B18="",$C18=""),"",IF(E18+F18+G18=0,0,E18/(E18+F18+G18))) -> 0 | I18: =IF(AND($B18="",$C18=""),"",SUMIFS($G$31:$G$260,$H$31:$H$260,IF($B18="","*",$B18),$C$31:$C$260,IF($C18="","*",$C18),$R$31:$R$260,1)) -> 0
D19: =IF(AND($B19="",$C19=""),"",SUMIFS($R$31:$R$260,$H$31:$H$260,IF($B19="","*",$B19),$C$31:$C$260,IF($C19="","*",$C19),$S$31:$S$260,"يعمل")) | E19: =IF(AND($B19="",$C19=""),"",SUMIFS($R$31:$R$260,$H$31:$H$260,IF($B19="","*",$B19),$C$31:$C$260,IF($C19="","*",$C19),$P$31:$P$260,"حقق")) | F19: =IF(AND($B19="",$C19=""),"",SUMIFS($R$31:$R$260,$H$31:$H$260,IF($B19="","*",$B19),$C$31:$C$260,IF($C19="","*",$C19),$P$31:$P$260,"قريب")) | G19: =IF(AND($B19="",$C19=""),"",SUMIFS($R$31:$R$260,$H$31:$H$260,IF($B19="","*",$B19),$C$31:$C$260,IF($C19="","*",$C19),$P$31:$P$260,"بعيد")) | H19: =IF(AND($B19="",$C19=""),"",IF(E19+F19+G19=0,0,E19/(E19+F19+G19))) | I19: =IF(AND($B19="",$C19=""),"",SUMIFS($G$31:$G$260,$H$31:$H$260,IF($B19="","*",$B19),$C$31:$C$260,IF($C19="","*",$C19),$R$31:$R$260,1))
D20: =IF(AND($B20="",$C20=""),"",SUMIFS($R$31:$R$260,$H$31:$H$260,IF($B20="","*",$B20),$C$31:$C$260,IF($C20="","*",$C20),$S$31:$S$260,"يعمل")) | E20: =IF(AND($B20="",$C20=""),"",SUMIFS($R$31:$R$260,$H$31:$H$260,IF($B20="","*",$B20),$C$31:$C$260,IF($C20="","*",$C20),$P$31:$P$260,"حقق")) | F20: =IF(AND($B20="",$C20=""),"",SUMIFS($R$31:$R$260,$H$31:$H$260,IF($B20="","*",$B20),$C$31:$C$260,IF($C20="","*",$C20),$P$31:$P$260,"قريب")) | G20: =IF(AND($B20="",$C20=""),"",SUMIFS($R$31:$R$260,$H$31:$H$260,IF($B20="","*",$B20),$C$31:$C$260,IF($C20="","*",$C20),$P$31:$P$260,"بعيد")) | H20: =IF(AND($B20="",$C20=""),"",IF(E20+F20+G20=0,0,E20/(E20+F20+G20))) | I20: =IF(AND($B20="",$C20=""),"",SUMIFS($G$31:$G$260,$H$31:$H$260,IF($B20="","*",$B20),$C$31:$C$260,IF($C20="","*",$C20),$R$31:$R$260,1))
D21: =IF(AND($B21="",$C21=""),"",SUMIFS($R$31:$R$260,$H$31:$H$260,IF($B21="","*",$B21),$C$31:$C$260,IF($C21="","*",$C21),$S$31:$S$260,"يعمل")) | E21: =IF(AND($B21="",$C21=""),"",SUMIFS($R$31:$R$260,$H$31:$H$260,IF($B21="","*",$B21),$C$31:$C$260,IF($C21="","*",$C21),$P$31:$P$260,"حقق")) | F21: =IF(AND($B21="",$C21=""),"",SUMIFS($R$31:$R$260,$H$31:$H$260,IF($B21="","*",$B21),$C$31:$C$260,IF($C21="","*",$C21),$P$31:$P$260,"قريب")) | G21: =IF(AND($B21="",$C21=""),"",SUMIFS($R$31:$R$260,$H$31:$H$260,IF($B21="","*",$B21),$C$31:$C$260,IF($C21="","*",$C21),$P$31:$P$260,"بعيد")) | H21: =IF(AND($B21="",$C21=""),"",IF(E21+F21+G21=0,0,E21/(E21+F21+G21))) | I21: =IF(AND($B21="",$C21=""),"",SUMIFS($G$31:$G$260,$H$31:$H$260,IF($B21="","*",$B21),$C$31:$C$260,IF($C21="","*",$C21),$R$31:$R$260,1))
C22: ترك العمل | D22: =SUMIFS($R$31:$R$260,$P$31:$P$260,"مستبعد (ترك العمل)") -> 3
C23: اجازه | D23: =SUMIFS($R$31:$R$260,$P$31:$P$260,"مستبعد (اجازة)") -> 4
C24: الإجمالي | D24: =SUMIFS($R$31:$R$260,$S$31:$S$260,"يعمل") -> 167 | E24: =SUMIFS($R$31:$R$260,$P$31:$P$260,"حقق") -> 74 | F24: =SUMIFS($R$31:$R$260,$P$31:$P$260,"قريب") -> 15 | G24: =SUMIFS($R$31:$R$260,$P$31:$P$260,"بعيد") -> 28 | H24: =IF(E24+F24+G24=0,0,E24/(E24+F24+G24)) -> 0.63247863 | I24: =SUBTOTAL(109,$G$31:$G$260) -> 0
A26: ="حقق: وصل لهدفه — قريب: من "&TEXT(الإعدادات!$B$8,"0%")&" لأقل من هدفه — بعيد: أقل. اليوم اللي فيه طلبات = يوم احتساب، واليوم اللي مفيهوش طلبات = غياب. الجداول دي بتتغير مع الفلتر. اكتب اسم المشرف/المشروع في الجدول اللي فوق لو عايز صف جديد." -> حقق: وصل لهدفه — قريب: من 80% لأقل من هدفه — بعيد: أقل. اليوم اللي فيه طلبات = يوم احتساب، واليوم اللي مفيهوش طلبات = غياب. الجداول دي بتتغير مع الفلتر. اكتب اسم المشرف/المشروع في الجدول اللي فوق لو عايز صف جديد.
A28: تفاصيل المناديب
A29: =SUBTOTAL(102,$A$31:$A$260) -> 162 | B29: =SUBTOTAL(109,$R$31:$R$260) -> 0 | C29: الإجمالي | F29: =SUBTOTAL(109,F31:F260) -> 29722 | G29: =SUBTOTAL(109,G31:G260) -> 0 | I29: =SUBTOTAL(109,I31:I260) -> 1954 | K29: =SUBTOTAL(109,K31:K260) -> 127 | M29: =SUBTOTAL(109,M31:M260) -> 28254 | O29: =SUBTOTAL(109,O31:O260) -> 54013
A30: رقم الإقامة | B30: الاسم | C30: المشروع | D30: م | E30: الجهة | F30: إجمالي الطلبات | G30: شحنات امازون | H30: المشرف | I30: طلبات اليوم | J30: تاريخ البدء | K30: أيام الغياب | L30: أيام الاحتساب | M30: هدفه | N30: % من الهدف | O30: المتوقع للشهر | P30: التقييم | Q30: ملاحظات
A31: =IF('الإدخال اليومي'!$B5="","",IF('الإدخال اليومي'!A5="","",'الإدخال اليومي'!A5)) -> 2556808885 | B31: =IF('الإدخال اليومي'!$B5="","",IF('الإدخال اليومي'!B5="","",'الإدخال اليومي'!B5)) -> Robin Mia | C31: =IF('الإدخال اليومي'!$B5="","",IF('الإدخال اليومي'!C5="","",'الإدخال اليومي'!C5)) -> كيتا | D31: =IF($B31="","",1) -> 1 | E31: =IF('الإدخال اليومي'!$B5="","",IF('الإدخال اليومي'!AD5="","",'الإدخال اليومي'!AD5)) -> كفالة | F31: =IF($B31="","",'الإدخال اليومي'!I5) -> 442 | G31: =IF($B31="","",IF(N('الإدخال اليومي'!AG5)=0,"",'الإدخال اليومي'!AG5)) | H31: =IF('الإدخال اليومي'!$B5="","",IF('الإدخال اليومي'!AE5="","",'الإدخال اليومي'!AE5)) -> محمود خطاب | I31: =IF($B31="","",IFERROR(INDEX('الإدخال اليومي'!K5:AA5,MATCH(الإعدادات!$B$2,'الإدخال اليومي'!$K$3:$AA$3,0)),0)) -> 23 | J31: =IF('الإدخال اليومي'!$B5="","",IF('الإدخال اليومي'!F5="","",'الإدخال اليومي'!F5)) -> 45924 | K31: =IF($B31="","",N('الإدخال اليومي'!G5)+MAX(0,الإعدادات!$B$2-MAX(الإعدادات!$B$10+1,N(J31))+1)-SUMPRODUCT(('الإدخال اليومي'!$L5:$AA5>0)*('الإدخال اليومي'!$L$3:$AA$3>=MAX(الإعدادات!$B$10+1,N(J31)))*('الإدخال اليومي'!$L$3:$AA$3<=الإعدادات!$B$2))) -> 0 | L31: =IF($B31="","",MAX(0,الإعدادات!$B$10-IF(J31="",الإعدادات!$B$9,MAX(J31,الإعدادات!$B$9))+1-N('الإدخال اليومي'!G5))+SUMPRODUCT(('الإدخال اليومي'!$L5:$AA5>0)*('الإدخال اليومي'!$L$3:$AA$3>=MAX(الإعدادات!$B$10+1,N(J31)))*('الإدخال اليومي'!$L$3:$AA$3<=الإعدادات!$B$2))) -> 17 | M31: =IF($B31="","",IF(C31="امازون","",(IFERROR(INDEX(الإعدادات!$B$19:$B$22,MATCH(C31,الإعدادات!$A$19:$A$22,0)),الإعدادات!$B$3)/الإعدادات!$B$4)*L31)) -> 255 | N31: =IF($B31="","",IF(OR(M31="",M31=0),"",F31/M31)) -> 1.7333333 | O31: =IF($B31="","",IF(OR(C31="امازون",L31=0),"",ROUND(F31/L31*الإعدادات!$B$4,0))) -> 780 | P31: =IF($B31="","",IF('الإدخال اليومي'!AF5="لا يعمل","مستبعد (ترك العمل)",IF('الإدخال اليومي'!AF5="اجازه","مستبعد (اجازة)",IF(C31="امازون","امازون (شحنات)",IF(L31=0,"مستبعد (لم يعمل)",IF(F31>=M31,"حقق",IF(F31>=M31*الإعدادات!$B$8,"قريب","بعيد"))))))) -> حقق | Q31: =IF($B31="","",TRIM('الإدخال اليومي'!H5&IF(N('الإدخال اليومي'!AC5)>0," | + "&'الإدخال اليومي'!AC5&" طلب من "&'الإدخال اليومي'!AB5&" (محسوبة في الإجمالي)",""))) | R31: =IF($B31="",0,SUBTOTAL(103,B31)) -> 1 | S31: =IF($B31="","",IF('الإدخال اليومي'!AF5="","يعمل",'الإدخال اليومي'!AF5)) -> يعمل
A32: =IF('الإدخال اليومي'!$B6="","",IF('الإدخال اليومي'!A6="","",'الإدخال اليومي'!A6)) -> 2558834244 | B32: =IF('الإدخال اليومي'!$B6="","",IF('الإدخال اليومي'!B6="","",'الإدخال اليومي'!B6)) -> AHMARE ALI ASLAM | C32: =IF('الإدخال اليومي'!$B6="","",IF('الإدخال اليومي'!C6="","",'الإدخال اليومي'!C6)) -> كيتا | D32: =IF($B32="","",2) -> 2 | E32: =IF('الإدخال اليومي'!$B6="","",IF('الإدخال اليومي'!AD6="","",'الإدخال اليومي'!AD6)) -> كفالة | F32: =IF($B32="","",'الإدخال اليومي'!I6) -> 428 | G32: =IF($B32="","",IF(N('الإدخال اليومي'!AG6)=0,"",'الإدخال اليومي'!AG6)) | H32: =IF('الإدخال اليومي'!$B6="","",IF('الإدخال اليومي'!AE6="","",'الإدخال اليومي'!AE6)) -> محمود خطاب | I32: =IF($B32="","",IFERROR(INDEX('الإدخال اليومي'!K6:AA6,MATCH(الإعدادات!$B$2,'الإدخال اليومي'!$K$3:$AA$3,0)),0)) -> 28 | J32: =IF('الإدخال اليومي'!$B6="","",IF('الإدخال اليومي'!F6="","",'الإدخال اليومي'!F6)) -> 46029 | K32: =IF($B32="","",N('الإدخال اليومي'!G6)+MAX(0,الإعدادات!$B$2-MAX(الإعدادات!$B$10+1,N(J32))+1)-SUMPRODUCT(('الإدخال اليومي'!$L6:$AA6>0)*('الإدخال اليومي'!$L$3:$AA$3>=MAX(الإعدادات!$B$10+1,N(J32)))*('الإدخال اليومي'!$L$3:$AA$3<=الإعدادات!$B$2))) -> 0 | L32: =IF($B32="","",MAX(0,الإعدادات!$B$10-IF(J32="",الإعدادات!$B$9,MAX(J32,الإعدادات!$B$9))+1-N('الإدخال اليومي'!G6))+SUMPRODUCT(('الإدخال اليومي'!$L6:$AA6>0)*('الإدخال اليومي'!$L$3:$AA$3>=MAX(الإعدادات!$B$10+1,N(J32)))*('الإدخال اليومي'!$L$3:$AA$3<=الإعدادات!$B$2))) -> 17 | M32: =IF($B32="","",IF(C32="امازون","",(IFERROR(INDEX(الإعدادات!$B$19:$B$22,MATCH(C32,الإعدادات!$A$19:$A$22,0)),الإعدادات!$B$3)/الإعدادات!$B$4)*L32)) -> 255 | N32: =IF($B32="","",IF(OR(M32="",M32=0),"",F32/M32)) -> 1.6784314 | O32: =IF($B32="","",IF(OR(C32="امازون",L32=0),"",ROUND(F32/L32*الإعدادات!$B$4,0))) -> 755 | P32: =IF($B32="","",IF('الإدخال اليومي'!AF6="لا يعمل","مستبعد (ترك العمل)",IF('الإدخال اليومي'!AF6="اجازه","مستبعد (اجازة)",IF(C32="امازون","امازون (شحنات)",IF(L32=0,"مستبعد (لم يعمل)",IF(F32>=M32,"حقق",IF(F32>=M32*الإعدادات!$B$8,"قريب","بعيد"))))))) -> حقق | Q32: =IF($B32="","",TRIM('الإدخال اليومي'!H6&IF(N('الإدخال اليومي'!AC6)>0," | + "&'الإدخال اليومي'!AC6&" طلب من "&'الإدخال اليومي'!AB6&" (محسوبة في الإجمالي)",""))) | R32: =IF($B32="",0,SUBTOTAL(103,B32)) -> 1 | S32: =IF($B32="","",IF('الإدخال اليومي'!AF6="","يعمل",'الإدخال اليومي'!AF6)) -> يعمل
A33: =IF('الإدخال اليومي'!$B7="","",IF('الإدخال اليومي'!A7="","",'الإدخال اليومي'!A7)) -> 2636257749 | B33: =IF('الإدخال اليومي'!$B7="","",IF('الإدخال اليومي'!B7="","",'الإدخال اليومي'!B7)) -> حسن احمد حسين جمال الدين | C33: =IF('الإدخال اليومي'!$B7="","",IF('الإدخال اليومي'!C7="","",'الإدخال اليومي'!C7)) -> كيتا | D33: =IF($B33="","",3) -> 3 | E33: =IF('الإدخال اليومي'!$B7="","",IF('الإدخال اليومي'!AD7="","",'الإدخال اليومي'!AD7)) -> فري لانسر | F33: =IF($B33="","",'الإدخال اليومي'!I7) -> 417 | G33: =IF($B33="","",IF(N('الإدخال اليومي'!AG7)=0,"",'الإدخال اليومي'!AG7)) | H33: =IF('الإدخال اليومي'!$B7="","",IF('الإدخال اليومي'!AE7="","",'الإدخال اليومي'!AE7)) -> خالد عباس | I33: =IF($B33="","",IFERROR(INDEX('الإدخال اليومي'!K7:AA7,MATCH(الإعدادات!$B$2,'الإدخال اليومي'!$K$3:$AA$3,0)),0)) -> 26 | J33: =IF('الإدخال اليومي'!$B7="","",IF('الإدخال اليومي'!F7="","",'الإدخال اليومي'!F7)) -> 46250 | K33: =IF($B33="","",N('الإدخال اليومي'!G7)+MAX(0,الإعدادات!$B$2-MAX(الإعدادات!$B$10+1,N(J33))+1)-SUMPRODUCT(('الإدخال اليومي'!$L7:$AA7>0)*('الإدخال اليومي'!$L$3:$AA$3>=MAX(الإعدادات!$B$10+1,N(J33)))*('الإدخال اليومي'!$L$3:$AA$3<=الإعدادات!$B$2))) -> 0 | L33: =IF($B33="","",MAX(0,الإعدادات!$B$10-IF(J33="",الإعدادات!$B$9,MAX(J33,الإعدادات!$B$9))+1-N('الإدخال اليومي'!G7))+SUMPRODUCT(('الإدخال اليومي'!$L7:$AA7>0)*('الإدخال اليومي'!$L$3:$AA$3>=MAX(الإعدادات!$B$10+1,N(J33)))*('الإدخال اليومي'!$L$3:$AA$3<=الإعدادات!$B$2))) -> 17 | M33: =IF($B33="","",IF(C33="امازون","",(IFERROR(INDEX(الإعدادات!$B$19:$B$22,MATCH(C33,الإعدادات!$A$19:$A$22,0)),الإعدادات!$B$3)/الإعدادات!$B$4)*L33)) -> 255 | N33: =IF($B33="","",IF(OR(M33="",M33=0),"",F33/M33)) -> 1.6352941 | O33: =IF($B33="","",IF(OR(C33="امازون",L33=0),"",ROUND(F33/L33*الإعدادات!$B$4,0))) -> 736 | P33: =IF($B33="","",IF('الإدخال اليومي'!AF7="لا يعمل","مستبعد (ترك العمل)",IF('الإدخال اليومي'!AF7="اجازه","مستبعد (اجازة)",IF(C33="امازون","امازون (شحنات)",IF(L33=0,"مستبعد (لم يعمل)",IF(F33>=M33,"حقق",IF(F33>=M33*الإعدادات!$B$8,"قريب","بعيد"))))))) -> حقق | Q33: =IF($B33="","",TRIM('الإدخال اليومي'!H7&IF(N('الإدخال اليومي'!AC7)>0," | + "&'الإدخال اليومي'!AC7&" طلب من "&'الإدخال اليومي'!AB7&" (محسوبة في الإجمالي)",""))) | R33: =IF($B33="",0,SUBTOTAL(103,B33)) -> 1 | S33: =IF($B33="","",IF('الإدخال اليومي'!AF7="","يعمل",'الإدخال اليومي'!AF7)) -> يعمل
A34: =IF('الإدخال اليومي'!$B8="","",IF('الإدخال اليومي'!A8="","",'الإدخال اليومي'!A8)) -> 2566744484 | B34: =IF('الإدخال اليومي'!$B8="","",IF('الإدخال اليومي'!B8="","",'الإدخال اليومي'!B8)) -> Babar Ali | C34: =IF('الإدخال اليومي'!$B8="","",IF('الإدخال اليومي'!C8="","",'الإدخال اليومي'!C8)) -> كيتا | D34: =IF($B34="","",4) -> 4 | E34: =IF('الإدخال اليومي'!$B8="","",IF('الإدخال اليومي'!AD8="","",'الإدخال اليومي'!AD8)) -> كفالة | F34: =IF($B34="","",'الإدخال اليومي'!I8) -> 401 | G34: =IF($B34="","",IF(N('الإدخال اليومي'!AG8)=0,"",'الإدخال اليومي'!AG8)) | H34: =IF('الإدخال اليومي'!$B8="","",IF('الإدخال اليومي'!AE8="","",'الإدخال اليومي'!AE8)) -> محمود خطاب | I34: =IF($B34="","",IFERROR(INDEX('الإدخال اليومي'!K8:AA8,MATCH(الإعدادات!$B$2,'الإدخال اليومي'!$K$3:$AA$3,0)),0)) -> 20 | J34: =IF('الإدخال اليومي'!$B8="","",IF('الإدخال اليومي'!F8="","",'الإدخال اليومي'!F8)) -> 45534 | K34: =IF($B34="","",N('الإدخال اليومي'!G8)+MAX(0,الإعدادات!$B$2-MAX(الإعدادات!$B$10+1,N(J34))+1)-SUMPRODUCT(('الإدخال اليومي'!$L8:$AA8>0)*('الإدخال اليومي'!$L$3:$AA$3>=MAX(الإعدادات!$B$10+1,N(J34)))*('الإدخال اليومي'!$L$3:$AA$3<=الإعدادات!$B$2))) -> 0 | L34: =IF($B34="","",MAX(0,الإعدادات!$B$10-IF(J34="",الإعدادات!$B$9,MAX(J34,الإعدادات!$B$9))+1-N('الإدخال اليومي'!G8))+SUMPRODUCT(('الإدخال اليومي'!$L8:$AA8>0)*('الإدخال اليومي'!$L$3:$AA$3>=MAX(الإعدادات!$B$10+1,N(J34)))*('الإدخال اليومي'!$L$3:$AA$3<=الإعدادات!$B$2))) -> 17 | M34: =IF($B34="","",IF(C34="امازون","",(IFERROR(INDEX(الإعدادات!$B$19:$B$22,MATCH(C34,الإعدادات!$A$19:$A$22,0)),الإعدادات!$B$3)/الإعدادات!$B$4)*L34)) -> 255 | N34: =IF($B34="","",IF(OR(M34="",M34=0),"",F34/M34)) -> 1.572549 | O34: =IF($B34="","",IF(OR(C34="امازون",L34=0),"",ROUND(F34/L34*الإعدادات!$B$4,0))) -> 708 | P34: =IF($B34="","",IF('الإدخال اليومي'!AF8="لا يعمل","مستبعد (ترك العمل)",IF('الإدخال اليومي'!AF8="اجازه","مستبعد (اجازة)",IF(C34="امازون","امازون (شحنات)",IF(L34=0,"مستبعد (لم يعمل)",IF(F34>=M34,"حقق",IF(F34>=M34*الإعدادات!$B$8,"قريب","بعيد"))))))) -> حقق | Q34: =IF($B34="","",TRIM('الإدخال اليومي'!H8&IF(N('الإدخال اليومي'!AC8)>0," | + "&'الإدخال اليومي'!AC8&" طلب من "&'الإدخال اليومي'!AB8&" (محسوبة في الإجمالي)",""))) | R34: =IF($B34="",0,SUBTOTAL(103,B34)) -> 1 | S34: =IF($B34="","",IF('الإدخال اليومي'!AF8="","يعمل",'الإدخال اليومي'!AF8)) -> يعمل
A35: =IF('الإدخال اليومي'!$B9="","",IF('الإدخال اليومي'!A9="","",'الإدخال اليومي'!A9)) -> 2556809024 | B35: =IF('الإدخال اليومي'!$B9="","",IF('الإدخال اليومي'!B9="","",'الإدخال اليومي'!B9)) -> Md ELMAZED | C35: =IF('الإدخال اليومي'!$B9="","",IF('الإدخال اليومي'!C9="","",'الإدخال اليومي'!C9)) -> كيتا | D35: =IF($B35="","",5) -> 5 | E35: =IF('الإدخال اليومي'!$B9="","",IF('الإدخال اليومي'!AD9="","",'الإدخال اليومي'!AD9)) -> كفالة | F35: =IF($B35="","",'الإدخال اليومي'!I9) -> 409 | G35: =IF($B35="","",IF(N('الإدخال اليومي'!AG9)=0,"",'الإدخال اليومي'!AG9)) | H35: =IF('الإدخال اليومي'!$B9="","",IF('الإدخال اليومي'!AE9="","",'الإدخال اليومي'!AE9)) -> محمود خطاب | I35: =IF($B35="","",IFERROR(INDEX('الإدخال اليومي'!K9:AA9,MATCH(الإعدادات!$B$2,'الإدخال اليومي'!$K$3:$AA$3,0)),0)) -> 22 | J35: =IF('الإدخال اليومي'!$B9="","",IF('الإدخال اليومي'!F9="","",'الإدخال اليومي'!F9)) -> 45924 | K35: =IF($B35="","",N('الإدخال اليومي'!G9)+MAX(0,الإعدادات!$B$2-MAX(الإعدادات!$B$10+1,N(J35))+1)-SUMPRODUCT(('الإدخال اليومي'!$L9:$AA9>0)*('الإدخال اليومي'!$L$3:$AA$3>=MAX(الإعدادات!$B$10+1,N(J35)))*('الإدخال اليومي'!$L$3:$AA$3<=الإعدادات!$B$2))) -> 0 | L35: =IF($B35="","",MAX(0,الإعدادات!$B$10-IF(J35="",الإعدادات!$B$9,MAX(J35,الإعدادات!$B$9))+1-N('الإدخال اليومي'!G9))+SUMPRODUCT(('الإدخال اليومي'!$L9:$AA9>0)*('الإدخال اليومي'!$L$3:$AA$3>=MAX(الإعدادات!$B$10+1,N(J35)))*('الإدخال اليومي'!$L$3:$AA$3<=الإعدادات!$B$2))) -> 17 | M35: =IF($B35="","",IF(C35="امازون","",(IFERROR(INDEX(الإعدادات!$B$19:$B$22,MATCH(C35,الإعدادات!$A$19:$A$22,0)),الإعدادات!$B$3)/الإعدادات!$B$4)*L35)) -> 255 | N35: =IF($B35="","",IF(OR(M35="",M35=0),"",F35/M35)) -> 1.6039216 | O35: =IF($B35="","",IF(OR(C35="امازون",L35=0),"",ROUND(F35/L35*الإعدادات!$B$4,0))) -> 722 | P35: =IF($B35="","",IF('الإدخال اليومي'!AF9="لا يعمل","مستبعد (ترك العمل)",IF('الإدخال اليومي'!AF9="اجازه","مستبعد (اجازة)",IF(C35="امازون","امازون (شحنات)",IF(L35=0,"مستبعد (لم يعمل)",IF(F35>=M35,"حقق",IF(F35>=M35*الإعدادات!$B$8,"قريب","بعيد"))))))) -> حقق | Q35: =IF($B35="","",TRIM('الإدخال اليومي'!H9&IF(N('الإدخال اليومي'!AC9)>0," | + "&'الإدخال اليومي'!AC9&" طلب من "&'الإدخال اليومي'!AB9&" (محسوبة في الإجمالي)",""))) | R35: =IF($B35="",0,SUBTOTAL(103,B35)) -> 1 | S35: =IF($B35="","",IF('الإدخال اليومي'!AF9="","يعمل",'الإدخال اليومي'!AF9)) -> يعمل
A36: =IF('الإدخال اليومي'!$B10="","",IF('الإدخال اليومي'!A10="","",'الإدخال اليومي'!A10)) -> 2555618590 | B36: =IF('الإدخال اليومي'!$B10="","",IF('الإدخال اليومي'!B10="","",'الإدخال اليومي'!B10)) -> MOHAMMED BAKRE | C36: =IF('الإدخال اليومي'!$B10="","",IF('الإدخال اليومي'!C10="","",'الإدخال اليومي'!C10)) -> كيتا | D36: =IF($B36="","",6) -> 6 | E36: =IF('الإدخال اليومي'!$B10="","",IF('الإدخال اليومي'!AD10="","",'الإدخال اليومي'!AD10)) -> كفالة | F36: =IF($B36="","",'الإدخال اليومي'!I10) -> 397 | G36: =IF($B36="","",IF(N('الإدخال اليومي'!AG10)=0,"",'الإدخال اليومي'!AG10)) | H36: =IF('الإدخال اليومي'!$B10="","",IF('الإدخال اليومي'!AE10="","",'الإدخال اليومي'!AE10)) -> محمود خطاب | I36: =IF($B36="","",IFERROR(INDEX('الإدخال اليومي'!K10:AA10,MATCH(الإعدادات!$B$2,'الإدخال اليومي'!$K$3:$AA$3,0)),0)) -> 22 | J36: =IF('الإدخال اليومي'!$B10="","",IF('الإدخال اليومي'!F10="","",'الإدخال اليومي'!F10)) -> 45322 | K36: =IF($B36="","",N('الإدخال اليومي'!G10)+MAX(0,الإعدادات!$B$2-MAX(الإعدادات!$B$10+1,N(J36))+1)-SUMPRODUCT(('الإدخال اليومي'!$L10:$AA10>0)*('الإدخال اليومي'!$L$3:$AA$3>=MAX(الإعدادات!$B$10+1,N(J36)))*('الإدخال اليومي'!$L$3:$AA$3<=الإعدادات!$B$2))) -> 0 | L36: =IF($B36="","",MAX(0,الإعدادات!$B$10-IF(J36="",الإعدادات!$B$9,MAX(J36,الإعدادات!$B$9))+1-N('الإدخال اليومي'!G10))+SUMPRODUCT(('الإدخال اليومي'!$L10:$AA10>0)*('الإدخال اليومي'!$L$3:$AA$3>=MAX(الإعدادات!$B$10+1,N(J36)))*('الإدخال اليومي'!$L$3:$AA$3<=الإعدادات!$B$2))) -> 17 | M36: =IF($B36="","",IF(C36="امازون","",(IFERROR(INDEX(الإعدادات!$B$19:$B$22,MATCH(C36,الإعدادات!$A$19:$A$22,0)),الإعدادات!$B$3)/الإعدادات!$B$4)*L36)) -> 255 | N36: =IF($B36="","",IF(OR(M36="",M36=0),"",F36/M36)) -> 1.5568627 | O36: =IF($B36="","",IF(OR(C36="امازون",L36=0),"",ROUND(F36/L36*الإعدادات!$B$4,0))) -> 701 | P36: =IF($B36="","",IF('الإدخال اليومي'!AF10="لا يعمل","مستبعد (ترك العمل)",IF('الإدخال اليومي'!AF10="اجازه","مستبعد (اجازة)",IF(C36="امازون","امازون (شحنات)",IF(L36=0,"مستبعد (لم يعمل)",IF(F36>=M36,"حقق",IF(F36>=M36*الإعدادات!$B$8,"قريب","بعيد"))))))) -> حقق | Q36: =IF($B36="","",TRIM('الإدخال اليومي'!H10&IF(N('الإدخال اليومي'!AC10)>0," | + "&'الإدخال اليومي'!AC10&" طلب من "&'الإدخال اليومي'!AB10&" (محسوبة في الإجمالي)",""))) | R36: =IF($B36="",0,SUBTOTAL(103,B36)) -> 1 | S36: =IF($B36="","",IF('الإدخال اليومي'!AF10="","يعمل",'الإدخال اليومي'!AF10)) -> يعمل
A37: =IF('الإدخال اليومي'!$B11="","",IF('الإدخال اليومي'!A11="","",'الإدخال اليومي'!A11)) -> 2588682613 | B37: =IF('الإدخال اليومي'!$B11="","",IF('الإدخال اليومي'!B11="","",'الإدخال اليومي'!B11)) -> قمر الحسن | C37: =IF('الإدخال اليومي'!$B11="","",IF('الإدخال اليومي'!C11="","",'الإدخال اليومي'!C11)) -> كيتا | D37: =IF($B37="","",7) -> 7 | E37: =IF('الإدخال اليومي'!$B11="","",IF('الإدخال اليومي'!AD11="","",'الإدخال اليومي'!AD11)) -> فري لانسر | F37: =IF($B37="","",'الإدخال اليومي'!I11) -> 387 | G37: =IF($B37="","",IF(N('الإدخال اليومي'!AG11)=0,"",'الإدخال اليومي'!AG11)) | H37: =IF('الإدخال اليومي'!$B11="","",IF('الإدخال اليومي'!AE11="","",'الإدخال اليومي'!AE11)) -> خالد عباس | I37: =IF($B37="","",IFERROR(INDEX('الإدخال اليومي'!K11:AA11,MATCH(الإعدادات!$B$2,'الإدخال اليومي'!$K$3:$AA$3,0)),0)) -> 17 | J37: =IF('الإدخال اليومي'!$B11="","",IF('الإدخال اليومي'!F11="","",'الإدخال اليومي'!F11)) -> 46204 | K37: =IF($B37="","",N('الإدخال اليومي'!G11)+MAX(0,الإعدادات!$B$2-MAX(الإعدادات!$B$10+1,N(J37))+1)-SUMPRODUCT(('الإدخال اليومي'!$L11:$AA11>0)*('الإدخال اليومي'!$L$3:$AA$3>=MAX(الإعدادات!$B$10+1,N(J37)))*('الإدخال اليومي'!$L$3:$AA$3<=الإعدادات!$B$2))) -> 0 | L37: =IF($B37="","",MAX(0,الإعدادات!$B$10-IF(J37="",الإعدادات!$B$9,MAX(J37,الإعدادات!$B$9))+1-N('الإدخال اليومي'!G11))+SUMPRODUCT(('الإدخال اليومي'!$L11:$AA11>0)*('الإدخال اليومي'!$L$3:$AA$3>=MAX(الإعدادات!$B$10+1,N(J37)))*('الإدخال اليومي'!$L$3:$AA$3<=الإعدادات!$B$2))) -> 17 | M37: =IF($B37="","",IF(C37="امازون","",(IFERROR(INDEX(الإعدادات!$B$19:$B$22,MATCH(C37,الإعدادات!$A$19:$A$22,0)),الإعدادات!$B$3)/الإعدادات!$B$4)*L37)) -> 255 | N37: =IF($B37="","",IF(OR(M37="",M37=0),"",F37/M37)) -> 1.5176471 | O37: =IF($B37="","",IF(OR(C37="امازون",L37=0),"",ROUND(F37/L37*الإعدادات!$B$4,0))) -> 683 | P37: =IF($B37="","",IF('الإدخال اليومي'!AF11="لا يعمل","مستبعد (ترك العمل)",IF('الإدخال اليومي'!AF11="اجازه","مستبعد (اجازة)",IF(C37="امازون","امازون (شحنات)",IF(L37=0,"مستبعد (لم يعمل)",IF(F37>=M37,"حقق",IF(F37>=M37*الإعدادات!$B$8,"قريب","بعيد"))))))) -> حقق | Q37: =IF($B37="","",TRIM('الإدخال اليومي'!H11&IF(N('الإدخال اليومي'!AC11)>0," | + "&'الإدخال اليومي'!AC11&" طلب من "&'الإدخال اليومي'!AB11&" (محسوبة في الإجمالي)",""))) | R37: =IF($B37="",0,SUBTOTAL(103,B37)) -> 1 | S37: =IF($B37="","",IF('الإدخال اليومي'!AF11="","يعمل",'الإدخال اليومي'!AF11)) -> يعمل
A38: =IF('الإدخال اليومي'!$B12="","",IF('الإدخال اليومي'!A12="","",'الإدخال اليومي'!A12)) -> 2591742545 | B38: =IF('الإدخال اليومي'!$B12="","",IF('الإدخال اليومي'!B12="","",'الإدخال اليومي'!B12)) -> مصطفى محمود احمد | C38: =IF('الإدخال اليومي'!$B12="","",IF('الإدخال اليومي'!C12="","",'الإدخال اليومي'!C12)) -> كيتا | D38: =IF($B38="","",8) -> 8 | E38: =IF('الإدخال اليومي'!$B12="","",IF('الإدخال اليومي'!AD12="","",'الإدخال اليومي'!AD12)) -> فري لانسر | F38: =IF($B38="","",'الإدخال اليومي'!I12) -> 358 | G38: =IF($B38="","",IF(N('الإدخال اليومي'!AG12)=0,"",'الإدخال اليومي'!AG12)) | H38: =IF('الإدخال اليومي'!$B12="","",IF('الإدخال اليومي'!AE12="","",'الإدخال اليومي'!AE12)) -> خالد عباس | I38: =IF($B38="","",IFERROR(INDEX('الإدخال اليومي'!K12:AA12,MATCH(الإعدادات!$B$2,'الإدخال اليومي'!$K$3:$AA$3,0)),0)) -> 15 | J38: =IF('الإدخال اليومي'!$B12="","",IF('الإدخال اليومي'!F12="","",'الإدخال اليومي'!F12)) -> 46204 | K38: =IF($B38="","",N('الإدخال اليومي'!G12)+MAX(0,الإعدادات!$B$2-MAX(الإعدادات!$B$10+1,N(J38))+1)-SUMPRODUCT(('الإدخال اليومي'!$L12:$AA12>0)*('الإدخال اليومي'!$L$3:$AA$3>=MAX(الإعدادات!$B$10+1,N(J38)))*('الإدخال اليومي'!$L$3:$AA$3<=الإعدادات!$B$2))) -> 1 | L38: =IF($B38="","",MAX(0,الإعدادات!$B$10-IF(J38="",الإعدادات!$B$9,MAX(J38,الإعدادات!$B$9))+1-N('الإدخال اليومي'!G12))+SUMPRODUCT(('الإدخال اليومي'!$L12:$AA12>0)*('الإدخال اليومي'!$L$3:$AA$3>=MAX(الإعدادات!$B$10+1,N(J38)))*('الإدخال اليومي'!$L$3:$AA$3<=الإعدادات!$B$2))) -> 16 | M38: =IF($B38="","",IF(C38="امازون","",(IFERROR(INDEX(الإعدادات!$B$19:$B$22,MATCH(C38,الإعدادات!$A$19:$A$22,0)),الإعدادات!$B$3)/الإعدادات!$B$4)*L38)) -> 240 | N38: =IF($B38="","",IF(OR(M38="",M38=0),"",F38/M38)) -> 1.4916667 | O38: =IF($B38="","",IF(OR(C38="امازون",L38=0),"",ROUND(F38/L38*الإعدادات!$B$4,0))) -> 671 | P38: =IF($B38="","",IF('الإدخال اليومي'!AF12="لا يعمل","مستبعد (ترك العمل)",IF('الإدخال اليومي'!AF12="اجازه","مستبعد (اجازة)",IF(C38="امازون","امازون (شحنات)",IF(L38=0,"مستبعد (لم يعمل)",IF(F38>=M38,"حقق",IF(F38>=M38*الإعدادات!$B$8,"قريب","بعيد"))))))) -> حقق | Q38: =IF($B38="","",TRIM('الإدخال اليومي'!H12&IF(N('الإدخال اليومي'!AC12)>0," | + "&'الإدخال اليومي'!AC12&" طلب من "&'الإدخال اليومي'!AB12&" (محسوبة في الإجمالي)",""))) | R38: =IF($B38="",0,SUBTOTAL(103,B38)) -> 1 | S38: =IF($B38="","",IF('الإدخال اليومي'!AF12="","يعمل",'الإدخال اليومي'!AF12)) -> يعمل
A39: =IF('الإدخال اليومي'!$B13="","",IF('الإدخال اليومي'!A13="","",'الإدخال اليومي'!A13)) -> 2586734259 | B39: =IF('الإدخال اليومي'!$B13="","",IF('الإدخال اليومي'!B13="","",'الإدخال اليومي'!B13)) -> RAFI MD IBRAHIM | C39: =IF('الإدخال اليومي'!$B13="","",IF('الإدخال اليومي'!C13="","",'الإدخال اليومي'!C13)) -> كيتا | D39: =IF($B39="","",9) -> 9 | E39: =IF('الإدخال اليومي'!$B13="","",IF('الإدخال اليومي'!AD13="","",'الإدخال اليومي'!AD13)) -> فري لانسر | F39: =IF($B39="","",'الإدخال اليومي'!I13) -> 370 | G39: =IF($B39="","",IF(N('الإدخال اليومي'!AG13)=0,"",'الإدخال اليومي'!AG13)) | H39: =IF('الإدخال اليومي'!$B13="","",IF('الإدخال اليومي'!AE13="","",'الإدخال اليومي'!AE13)) -> خالد عباس | I39: =IF($B39="","",IFERROR(INDEX('الإدخال اليومي'!K13:AA13,MATCH(الإعدادات!$B$2,'الإدخال اليومي'!$K$3:$AA$3,0)),0)) -> 15 | J39: =IF('الإدخال اليومي'!$B13="","",IF('الإدخال اليومي'!F13="","",'الإدخال اليومي'!F13)) -> 46284 | K39: =IF($B39="","",N('الإدخال اليومي'!G13)+MAX(0,الإعدادات!$B$2-MAX(الإعدادات!$B$10+1,N(J39))+1)-SUMPRODUCT(('الإدخال اليومي'!$L13:$AA13>0)*('الإدخال اليومي'!$L$3:$AA$3>=MAX(الإعدادات!$B$10+1,N(J39)))*('الإدخال اليومي'!$L$3:$AA$3<=الإعدادات!$B$2))) -> 0 | L39: =IF($B39="","",MAX(0,الإعدادات!$B$10-IF(J39="",الإعدادات!$B$9,MAX(J39,الإعدادات!$B$9))+1-N('الإدخال اليومي'!G13))+SUMPRODUCT(('الإدخال اليومي'!$L13:$AA13>0)*('الإدخال اليومي'!$L$3:$AA$3>=MAX(الإعدادات!$B$10+1,N(J39)))*('الإدخال اليومي'!$L$3:$AA$3<=الإعدادات!$B$2))) -> 17 | M39: =IF($B39="","",IF(C39="امازون","",(IFERROR(INDEX(الإعدادات!$B$19:$B$22,MATCH(C39,الإعدادات!$A$19:$A$22,0)),الإعدادات!$B$3)/الإعدادات!$B$4)*L39)) -> 255 | N39: =IF($B39="","",IF(OR(M39="",M39=0),"",F39/M39)) -> 1.4509804 | O39: =IF($B39="","",IF(OR(C39="امازون",L39=0),"",ROUND(F39/L39*الإعدادات!$B$4,0))) -> 653 | P39: =IF($B39="","",IF('الإدخال اليومي'!AF13="لا يعمل","مستبعد (ترك العمل)",IF('الإدخال اليومي'!AF13="اجازه","مستبعد (اجازة)",IF(C39="امازون","امازون (شحنات)",IF(L39=0,"مستبعد (لم يعمل)",IF(F39>=M39,"حقق",IF(F39>=M39*الإعدادات!$B$8,"قريب","بعيد"))))))) -> حقق | Q39: =IF($B39="","",TRIM('الإدخال اليومي'!H13&IF(N('الإدخال اليومي'!AC13)>0," | + "&'الإدخال اليومي'!AC13&" طلب من "&'الإدخال اليومي'!AB13&" (محسوبة في الإجمالي)",""))) | R39: =IF($B39="",0,SUBTOTAL(103,B39)) -> 1 | S39: =IF($B39="","",IF('الإدخال اليومي'!AF13="","يعمل",'الإدخال اليومي'!AF13)) -> يعمل
A40: =IF('الإدخال اليومي'!$B14="","",IF('الإدخال اليومي'!A14="","",'الإدخال اليومي'!A14)) -> 2567991936 | B40: =IF('الإدخال اليومي'!$B14="","",IF('الإدخال اليومي'!B14="","",'الإدخال اليومي'!B14)) -> SABUJ SK | C40: =IF('الإدخال اليومي'!$B14="","",IF('الإدخال اليومي'!C14="","",'الإدخال اليومي'!C14)) -> كيتا | D40: =IF($B40="","",10) -> 10 | E40: =IF('الإدخال اليومي'!$B14="","",IF('الإدخال اليومي'!AD14="","",'الإدخال اليومي'!AD14)) -> كفالة | F40: =IF($B40="","",'الإدخال اليومي'!I14) -> 393 | G40: =IF($B40="","",IF(N('الإدخال اليومي'!AG14)=0,"",'الإدخال اليومي'!AG14)) | H40: =IF('الإدخال اليومي'!$B14="","",IF('الإدخال اليومي'!AE14="","",'الإدخال اليومي'!AE14)) -> محمود خطاب | I40: =IF($B40="","",IFERROR(INDEX('الإدخال اليومي'!K14:AA14,MATCH(الإعدادات!$B$2,'الإدخال اليومي'!$K$3:$AA$3,0)),0)) -> 26 | J40: =IF('الإدخال اليومي'!$B14="","",IF('الإدخال اليومي'!F14="","",'الإدخال اليومي'!F14)) -> 45412 | K40: =IF($B40="","",N('الإدخال اليومي'!G14)+MAX(0,الإعدادات!$B$2-MAX(الإعدادات!$B$10+1,N(J40))+1)-SUMPRODUCT(('الإدخال اليومي'!$L14:$AA14>0)*('الإدخال اليومي'!$L$3:$AA$3>=MAX(الإعدادات!$B$10+1,N(J40)))*('الإدخال اليومي'!$L$3:$AA$3<=الإعدادات!$B$2))) -> 0 | L40: =IF($B40="","",MAX(0,الإعدادات!$B$10-IF(J40="",الإعدادات!$B$9,MAX(J40,الإعدادات!$B$9))+1-N('الإدخال اليومي'!G14))+SUMPRODUCT(('الإدخال اليومي'!$L14:$AA14>0)*('الإدخال اليومي'!$L$3:$AA$3>=MAX(الإعدادات!$B$10+1,N(J40)))*('الإدخال اليومي'!$L$3:$AA$3<=الإعدادات!$B$2))) -> 17 | M40: =IF($B40="","",IF(C40="امازون","",(IFERROR(INDEX(الإعدادات!$B$19:$B$22,MATCH(C40,الإعدادات!$A$19:$A$22,0)),الإعدادات!$B$3)/الإعدادات!$B$4)*L40)) -> 255 | N40: =IF($B40="","",IF(OR(M40="",M40=0),"",F40/M40)) -> 1.5411765 | O40: =IF($B40="","",IF(OR(C40="امازون",L40=0),"",ROUND(F40/L40*الإعدادات!$B$4,0))) -> 694 | P40: =IF($B40="","",IF('الإدخال اليومي'!AF14="لا يعمل","مستبعد (ترك العمل)",IF('الإدخال اليومي'!AF14="اجازه","مستبعد (اجازة)",IF(C40="امازون","امازون (شحنات)",IF(L40=0,"مستبعد (لم يعمل)",IF(F40>=M40,"حقق",IF(F40>=M40*الإعدادات!$B$8,"قريب","بعيد"))))))) -> حقق | Q40: =IF($B40="","",TRIM('الإدخال اليومي'!H14&IF(N('الإدخال اليومي'!AC14)>0," | + "&'الإدخال اليومي'!AC14&" طلب من "&'الإدخال اليومي'!AB14&" (محسوبة في الإجمالي)",""))) | R40: =IF($B40="",0,SUBTOTAL(103,B40)) -> 1 | S40: =IF($B40="","",IF('الإدخال اليومي'!AF14="","يعمل",'الإدخال اليومي'!AF14)) -> يعمل
A41: =IF('الإدخال اليومي'!$B15="","",IF('الإدخال اليومي'!A15="","",'الإدخال اليومي'!A15)) -> 2585711043 | B41: =IF('الإدخال اليومي'!$B15="","",IF('الإدخال اليومي'!B15="","",'الإدخال اليومي'!B15)) -> هريدوى تشاندرا | C41: =IF('الإدخال اليومي'!$B15="","",IF('الإدخال اليومي'!C15="","",'الإدخال اليومي'!C15)) -> كيتا | D41: =IF($B41="","",11) -> 11 | E41: =IF('الإدخال اليومي'!$B15="","",IF('الإدخال اليومي'!AD15="","",'الإدخال اليومي'!AD15)) -> فري لانسر | F41: =IF($B41="","",'الإدخال اليومي'!I15) -> 383 | G41: =IF($B41="","",IF(N('الإدخال اليومي'!AG15)=0,"",'الإدخال اليومي'!AG15)) | H41: =IF('الإدخال اليومي'!$B15="","",IF('الإدخال اليومي'!AE15="","",'الإدخال اليومي'!AE15)) -> خالد عباس | I41: =IF($B41="","",IFERROR(INDEX('الإدخال اليومي'!K15:AA15,MATCH(الإعدادات!$B$2,'الإدخال اليومي'!$K$3:$AA$3,0)),0)) -> 17 | J41: =IF('الإدخال اليومي'!$B15="","",IF('الإدخال اليومي'!F15="","",'الإدخال اليومي'!F15)) -> 46204 | K41: =IF($B41="","",N('الإدخال اليومي'!G15)+MAX(0,الإعدادات!$B$2-MAX(الإعدادات!$B$10+1,N(J41))+1)-SUMPRODUCT(('الإدخال اليومي'!$L15:$AA15>0)*('الإدخال اليومي'!$L$3:$AA$3>=MAX(الإعدادات!$B$10+1,N(J41)))*('الإدخال اليومي'!$L$3:$AA$3<=الإعدادات!$B$2))) -> 0 | L41: =IF($B41="","",MAX(0,الإعدادات!$B$10-IF(J41="",الإعدادات!$B$9,MAX(J41,الإعدادات!$B$9))+1-N('الإدخال اليومي'!G15))+SUMPRODUCT(('الإدخال اليومي'!$L15:$AA15>0)*('الإدخال اليومي'!$L$3:$AA$3>=MAX(الإعدادات!$B$10+1,N(J41)))*('الإدخال اليومي'!$L$3:$AA$3<=الإعدادات!$B$2))) -> 17 | M41: =IF($B41="","",IF(C41="امازون","",(IFERROR(INDEX(الإعدادات!$B$19:$B$22,MATCH(C41,الإعدادات!$A$19:$A$22,0)),الإعدادات!$B$3)/الإعدادات!$B$4)*L41)) -> 255 | N41: =IF($B41="","",IF(OR(M41="",M41=0),"",F41/M41)) -> 1.5019608 | O41: =IF($B41="","",IF(OR(C41="امازون",L41=0),"",ROUND(F41/L41*الإعدادات!$B$4,0))) -> 676 | P41: =IF($B41="","",IF('الإدخال اليومي'!AF15="لا يعمل","مستبعد (ترك العمل)",IF('الإدخال اليومي'!AF15="اجازه","مستبعد (اجازة)",IF(C41="امازون","امازون (شحنات)",IF(L41=0,"مستبعد (لم يعمل)",IF(F41>=M41,"حقق",IF(F41>=M41*الإعدادات!$B$8,"قريب","بعيد"))))))) -> حقق | Q41: =IF($B41="","",TRIM('الإدخال اليومي'!H15&IF(N('الإدخال اليومي'!AC15)>0," | + "&'الإدخال اليومي'!AC15&" طلب من "&'الإدخال اليومي'!AB15&" (محسوبة في الإجمالي)",""))) | R41: =IF($B41="",0,SUBTOTAL(103,B41)) -> 1 | S41: =IF($B41="","",IF('الإدخال اليومي'!AF15="","يعمل",'الإدخال اليومي'!AF15)) -> يعمل
A42: =IF('الإدخال اليومي'!$B16="","",IF('الإدخال اليومي'!A16="","",'الإدخال اليومي'!A16)) -> 2569644962 | B42: =IF('الإدخال اليومي'!$B16="","",IF('الإدخال اليومي'!B16="","",'الإدخال اليومي'!B16)) -> KHAYRUL ISLAM | C42: =IF('الإدخال اليومي'!$B16="","",IF('الإدخال اليومي'!C16="","",'الإدخال اليومي'!C16)) -> كيتا | D42: =IF($B42="","",12) -> 12 | E42: =IF('الإدخال اليومي'!$B16="","",IF('الإدخال اليومي'!AD16="","",'الإدخال اليومي'!AD16)) -> كفالة | F42: =IF($B42="","",'الإدخال اليومي'!I16) -> 342 | G42: =IF($B42="","",IF(N('الإدخال اليومي'!AG16)=0,"",'الإدخال اليومي'!AG16)) | H42: =IF('الإدخال اليومي'!$B16="","",IF('الإدخال اليومي'!AE16="","",'الإدخال اليومي'!AE16)) -> محمود خطاب | I42: =IF($B42="","",IFERROR(INDEX('الإدخال اليومي'!K16:AA16,MATCH(الإعدادات!$B$2,'الإدخال اليومي'!$K$3:$AA$3,0)),0)) -> 15 | J42: =IF('الإدخال اليومي'!$B16="","",IF('الإدخال اليومي'!F16="","",'الإدخال اليومي'!F16)) -> 46139 | K42: =IF($B42="","",N('الإدخال اليومي'!G16)+MAX(0,الإعدادات!$B$2-MAX(الإعدادات!$B$10+1,N(J42))+1)-SUMPRODUCT(('الإدخال اليومي'!$L16:$AA16>0)*('الإدخال اليومي'!$L$3:$AA$3>=MAX(الإعدادات!$B$10+1,N(J42)))*('الإدخال اليومي'!$L$3:$AA$3<=الإعدادات!$B$2))) -> 0 | L42: =IF($B42="","",MAX(0,الإعدادات!$B$10-IF(J42="",الإعدادات!$B$9,MAX(J42,الإعدادات!$B$9))+1-N('الإدخال اليومي'!G16))+SUMPRODUCT(('الإدخال اليومي'!$L16:$AA16>0)*('الإدخال اليومي'!$L$3:$AA$3>=MAX(الإعدادات!$B$10+1,N(J42)))*('الإدخال اليومي'!$L$3:$AA$3<=الإعدادات!$B$2))) -> 17 | M42: =IF($B42="","",IF(C42="امازون","",(IFERROR(INDEX(الإعدادات!$B$19:$B$22,MATCH(C42,الإعدادات!$A$19:$A$22,0)),الإعدادات!$B$3)/الإعدادات!$B$4)*L42)) -> 255 | N42: =IF($B42="","",IF(OR(M42="",M42=0),"",F42/M42)) -> 1.3411765 | O42: =IF($B42="","",IF(OR(C42="امازون",L42=0),"",ROUND(F42/L42*الإعدادات!$B$4,0))) -> 604 | P42: =IF($B42="","",IF('الإدخال اليومي'!AF16="لا يعمل","مستبعد (ترك العمل)",IF('الإدخال اليومي'!AF16="اجازه","مستبعد (اجازة)",IF(C42="امازون","امازون (شحنات)",IF(L42=0,"مستبعد (لم يعمل)",IF(F42>=M42,"حقق",IF(F42>=M42*الإعدادات!$B$8,"قريب","بعيد"))))))) -> حقق | Q42: =IF($B42="","",TRIM('الإدخال اليومي'!H16&IF(N('الإدخال اليومي'!AC16)>0," | + "&'الإدخال اليومي'!AC16&" طلب من "&'الإدخال اليومي'!AB16&" (محسوبة في الإجمالي)",""))) | R42: =IF($B42="",0,SUBTOTAL(103,B42)) -> 1 | S42: =IF($B42="","",IF('الإدخال اليومي'!AF16="","يعمل",'الإدخال اليومي'!AF16)) -> يعمل
A43: =IF('الإدخال اليومي'!$B17="","",IF('الإدخال اليومي'!A17="","",'الإدخال اليومي'!A17)) -> 2548474473 | B43: =IF('الإدخال اليومي'!$B17="","",IF('الإدخال اليومي'!B17="","",'الإدخال اليومي'!B17)) -> BELAL HOSEN | C43: =IF('الإدخال اليومي'!$B17="","",IF('الإدخال اليومي'!C17="","",'الإدخال اليومي'!C17)) -> كيتا | D43: =IF($B43="","",13) -> 13 | E43: =IF('الإدخال اليومي'!$B17="","",IF('الإدخال اليومي'!AD17="","",'الإدخال اليومي'!AD17)) -> كفالة | F43: =IF($B43="","",'الإدخال اليومي'!I17) -> 377 | G43: =IF($B43="","",IF(N('الإدخال اليومي'!AG17)=0,"",'الإدخال اليومي'!AG17)) | H43: =IF('الإدخال اليومي'!$B17="","",IF('الإدخال اليومي'!AE17="","",'الإدخال اليومي'!AE17)) -> محمود خطاب | I43: =IF($B43="","",IFERROR(INDEX('الإدخال اليومي'!K17:AA17,MATCH(الإعدادات!$B$2,'الإدخال اليومي'!$K$3:$AA$3,0)),0)) -> 29 | J43: =IF('الإدخال اليومي'!$B17="","",IF('الإدخال اليومي'!F17="","",'الإدخال اليومي'!F17)) -> 45351 | K43: =IF($B43="","",N('الإدخال اليومي'!G17)+MAX(0,الإعدادات!$B$2-MAX(الإعدادات!$B$10+1,N(J43))+1)-SUMPRODUCT(('الإدخال اليومي'!$L17:$AA17>0)*('الإدخال اليومي'!$L$3:$AA$3>=MAX(الإعدادات!$B$10+1,N(J43)))*('الإدخال اليومي'!$L$3:$AA$3<=الإعدادات!$B$2))) -> 0 | L43: =IF($B43="","",MAX(0,الإعدادات!$B$10-IF(J43="",الإعدادات!$B$9,MAX(J43,الإعدادات!$B$9))+1-N('الإدخال اليومي'!G17))+SUMPRODUCT(('الإدخال اليومي'!$L17:$AA17>0)*('الإدخال اليومي'!$L$3:$AA$3>=MAX(الإعدادات!$B$10+1,N(J43)))*('الإدخال اليومي'!$L$3:$AA$3<=الإعدادات!$B$2))) -> 17 | M43: =IF($B43="","",IF(C43="امازون","",(IFERROR(INDEX(الإعدادات!$B$19:$B$22,MATCH(C43,الإعدادات!$A$19:$A$22,0)),الإعدادات!$B$3)/الإعدادات!$B$4)*L43)) -> 255 | N43: =IF($B43="","",IF(OR(M43="",M43=0),"",F43/M43)) -> 1.4784314 | O43: =IF($B43="","",IF(OR(C43="امازون",L43=0),"",ROUND(F43/L43*الإعدادات!$B$4,0))) -> 665 | P43: =IF($B43="","",IF('الإدخال اليومي'!AF17="لا يعمل","مستبعد (ترك العمل)",IF('الإدخال اليومي'!AF17="اجازه","مستبعد (اجازة)",IF(C43="امازون","امازون (شحنات)",IF(L43=0,"مستبعد (لم يعمل)",IF(F43>=M43,"حقق",IF(F43>=M43*الإعدادات!$B$8,"قريب","بعيد"))))))) -> حقق | Q43: =IF($B43="","",TRIM('الإدخال اليومي'!H17&IF(N('الإدخال اليومي'!AC17)>0," | + "&'الإدخال اليومي'!AC17&" طلب من "&'الإدخال اليومي'!AB17&" (محسوبة في الإجمالي)",""))) | R43: =IF($B43="",0,SUBTOTAL(103,B43)) -> 1 | S43: =IF($B43="","",IF('الإدخال اليومي'!AF17="","يعمل",'الإدخال اليومي'!AF17)) -> يعمل
A44: =IF('الإدخال اليومي'!$B18="","",IF('الإدخال اليومي'!A18="","",'الإدخال اليومي'!A18)) -> 2560708006 | B44: =IF('الإدخال اليومي'!$B18="","",IF('الإدخال اليومي'!B18="","",'الإدخال اليومي'!B18)) -> زاكير اوسين | C44: =IF('الإدخال اليومي'!$B18="","",IF('الإدخال اليومي'!C18="","",'الإدخال اليومي'!C18)) -> كيتا | D44: =IF($B44="","",14) -> 14 | E44: =IF('الإدخال اليومي'!$B18="","",IF('الإدخال اليومي'!AD18="","",'الإدخال اليومي'!AD18)) -> فري لانسر | F44: =IF($B44="","",'الإدخال اليومي'!I18) -> 370 | G44: =IF($B44="","",IF(N('الإدخال اليومي'!AG18)=0,"",'الإدخال اليومي'!AG18)) | H44: =IF('الإدخال اليومي'!$B18="","",IF('الإدخال اليومي'!AE18="","",'الإدخال اليومي'!AE18)) -> خالد عباس | I44: =IF($B44="","",IFERROR(INDEX('الإدخال اليومي'!K18:AA18,MATCH(الإعدادات!$B$2,'الإدخال اليومي'!$K$3:$AA$3,0)),0)) -> 23 | J44: =IF('الإدخال اليومي'!$B18="","",IF('الإدخال اليومي'!F18="","",'الإدخال اليومي'!F18)) -> 46204 | K44: =IF($B44="","",N('الإدخال اليومي'!G18)+MAX(0,الإعدادات!$B$2-MAX(الإعدادات!$B$10+1,N(J44))+1)-SUMPRODUCT(('الإدخال اليومي'!$L18:$AA18>0)*('الإدخال اليومي'!$L$3:$AA$3>=MAX(الإعدادات!$B$10+1,N(J44)))*('الإدخال اليومي'!$L$3:$AA$3<=الإعدادات!$B$2))) -> 0 | L44: =IF($B44="","",MAX(0,الإعدادات!$B$10-IF(J44="",الإعدادات!$B$9,MAX(J44,الإعدادات!$B$9))+1-N('الإدخال اليومي'!G18))+SUMPRODUCT(('الإدخال اليومي'!$L18:$AA18>0)*('الإدخال اليومي'!$L$3:$AA$3>=MAX(الإعدادات!$B$10+1,N(J44)))*('الإدخال اليومي'!$L$3:$AA$3<=الإعدادات!$B$2))) -> 17 | M44: =IF($B44="","",IF(C44="امازون","",(IFERROR(INDEX(الإعدادات!$B$19:$B$22,MATCH(C44,الإعدادات!$A$19:$A$22,0)),الإعدادات!$B$3)/الإعدادات!$B$4)*L44)) -> 255 | N44: =IF($B44="","",IF(OR(M44="",M44=0),"",F44/M44)) -> 1.4509804 | O44: =IF($B44="","",IF(OR(C44="امازون",L44=0),"",ROUND(F44/L44*الإعدادات!$B$4,0))) -> 653 | P44: =IF($B44="","",IF('الإدخال اليومي'!AF18="لا يعمل","مستبعد (ترك العمل)",IF('الإدخال اليومي'!AF18="اجازه","مستبعد (اجازة)",IF(C44="امازون","امازون (شحنات)",IF(L44=0,"مستبعد (لم يعمل)",IF(F44>=M44,"حقق",IF(F44>=M44*الإعدادات!$B$8,"قريب","بعيد"))))))) -> حقق | Q44: =IF($B44="","",TRIM('الإدخال اليومي'!H18&IF(N('الإدخال اليومي'!AC18)>0," | + "&'الإدخال اليومي'!AC18&" طلب من "&'الإدخال اليومي'!AB18&" (محسوبة في الإجمالي)",""))) | R44: =IF($B44="",0,SUBTOTAL(103,B44)) -> 1 | S44: =IF($B44="","",IF('الإدخال اليومي'!AF18="","يعمل",'الإدخال اليومي'!AF18)) -> يعمل
...

Sheet الإدخال اليومي
A1: الإدخال اليومي للطلبات
A2: كل يوم اكتب طلبات كل مندوب في عمود تاريخ اليوم. اليوم اللي فيه طلبات بيتحسب يوم عمل، واليوم الفاضي أو صفر بيتحسب غياب ويتلوّن أحمر (تقدر تضيف Note على الخلية بسبب الغياب). اللي مش محقق اكتب سبب في عمود الملاحظات (بيتلوّن أحمر لو فاضي). امازون: اكتب الشحنات في عمود الشحنات.
A3: رقم الإقامة | B3: الاسم | C3: المشروع | D3: م | E3: الحالة / الجهة | F3: تاريخ البدء (لو بعد أول الشهر) | G3: أيام غياب أول الشهر (لحد الرصيد) | H3: ملاحظات (سبب عدم التحقيق) | I3: إجمالي الشهر | J3: ="إجمالي حتى "&TEXT(الإعدادات!$B$10,"dd/mm") -> إجمالي حتى 15/10 | K3: =الإعدادات!$B$10 -> 46310 | L3: =K3+1 -> 46311 | M3: =L3+1 -> 46312 | N3: =M3+1 -> 46313 | O3: =N3+1 -> 46314 | P3: =O3+1 -> 46315 | Q3: =P3+1 -> 46316 | R3: =Q3+1 -> 46317 | S3: =R3+1 -> 46318 | ... AA3: =Z3+1 -> 46326 | AB3: مشروع آخر اشتغل فيه | AC3: طلباته هناك (إجمالي الشهر) | AD3: الجهة | AE3: المشرف | AF3: الحالة | AG3: إجمالي الشحنات (امازون) | AH3: التقييم الحالي
A4: إجمالي اليوم | I4: =SUM(I5:I234) -> 29722 | J4: =SUM(J5:J234) -> 25615 | K4: =SUM(K5:K234) -> 2169 | L4: =SUM(L5:L234) -> 2153 | M4: =SUM(M5:M234) -> 1954 | N4: =SUM(N5:N234) -> 0 | O4: =SUM(O5:O234) -> 0 | P4: =SUM(P5:P234) -> 0 | ... AA4: =SUM(AA5:AA234) -> 0 | AG4: =SUM(AG5:AG234) -> 0
A5: 2556808885 | B5: Robin Mia | C5: كيتا | D5: =IF(B5="","",ROW()-4) -> 1 | E5: خطاب | F5: 45924 | I5: =IF(B5="","",J5+SUM(L5:AA5)+N(AC5)) -> 442 | J5: 389 | K5: 31 | L5: 30 | M5: 23 | AD5: كفالة | AE5: محمود خطاب | AF5: يعمل | AH5: =IF(B5="","",INDEX(التقرير!$P$31:$P$260,ROW()-4)) -> حقق
A6: 2558834244 | B6: AHMARE ALI ASLAM | C6: كيتا | D6: =IF(B6="","",ROW()-4) -> 2 | E6: خطاب | F6: 46029 | I6: =IF(B6="","",J6+SUM(L6:AA6)+N(AC6)) -> 428 | J6: 375 | K6: 1 | L6: 25 | M6: 28 | AD6: كفالة | AE6: محمود خطاب | AF6: يعمل | AH6: =IF(B6="","",INDEX(التقرير!$P$31:$P$260,ROW()-4)) -> حقق
A7: 2636257749 | B7: حسن احمد حسين جمال الدين | C7: كيتا | D7: =IF(B7="","",ROW()-4) -> 3 | E7: خالد | F7: 46250 | I7: =IF(B7="","",J7+SUM(L7:AA7)+N(AC7)) -> 417 | J7: 369 | K7: 27 | L7: 22 | M7: 26 | AD7: فري لانسر | AE7: خالد عباس | AF7: يعمل | AH7: =IF(B7="","",INDEX(التقرير!$P$31:$P$260,ROW()-4)) -> حقق
A8: 2566744484 | B8: Babar Ali | C8: كيتا | D8: =IF(B8="","",ROW()-4) -> 4 | E8: خطاب | F8: 45534 | I8: =IF(B8="","",J8+SUM(L8:AA8)+N(AC8)) -> 401 | J8: 360 | K8: 33 | L8: 21 | M8: 20 | AD8: كفالة | AE8: محمود خطاب | AF8: يعمل | AH8: =IF(B8="","",INDEX(التقرير!$P$31:$P$260,ROW()-4)) -> حقق
A9: 2556809024 | B9: Md ELMAZED | C9: كيتا | D9: =IF(B9="","",ROW()-4) -> 5 | E9: خطاب | F9: 45924 | I9: =IF(B9="","",J9+SUM(L9:AA9)+N(AC9)) -> 409 | J9: 358 | K9: 30 | L9: 29 | M9: 22 | AD9: كفالة | AE9: محمود خطاب | AF9: يعمل | AH9: =IF(B9="","",INDEX(التقرير!$P$31:$P$260,ROW()-4)) -> حقق
A10: 2555618590 | B10: MOHAMMED BAKRE | C10: كيتا | D10: =IF(B10="","",ROW()-4) -> 6 | E10: خطاب | F10: 45322 | I10: =IF(B10="","",J10+SUM(L10:AA10)+N(AC10)) -> 397 | J10: 349 | K10: 24 | L10: 26 | M10: 22 | AD10: كفالة | AE10: محمود خطاب | AF10: يعمل | AH10: =IF(B10="","",INDEX(التقرير!$P$31:$P$260,ROW()-4)) -> حقق
A11: 2588682613 | B11: قمر الحسن | C11: كيتا | D11: =IF(B11="","",ROW()-4) -> 7 | E11: خالد | F11: 46204 | I11: =IF(B11="","",J11+SUM(L11:AA11)+N(AC11)) -> 387 | J11: 346 | K11: 24 | L11: 24 | M11: 17 | AD11: فري لانسر | AE11: خالد عباس | AF11: يعمل | AH11: =IF(B11="","",INDEX(التقرير!$P$31:$P$260,ROW()-4)) -> حقق
A12: 2591742545 | B12: مصطفى محمود احمد | C12: كيتا | D12: =IF(B12="","",ROW()-4) -> 8 | E12: خالد | F12: 46204 | I12: =IF(B12="","",J12+SUM(L12:AA12)+N(AC12)) -> 358 | J12: 343 | K12: 22 | L12: 0 | M12: 15 | AD12: فري لانسر | AE12: خالد عباس | AF12: يعمل | AH12: =IF(B12="","",INDEX(التقرير!$P$31:$P$260,ROW()-4)) -> حقق
A13: 2586734259 | B13: RAFI MD IBRAHIM | C13: كيتا | D13: =IF(B13="","",ROW()-4) -> 9 | E13: خالد | F13: 46284 | I13: =IF(B13="","",J13+SUM(L13:AA13)+N(AC13)) -> 370 | J13: 342 | K13: 28 | L13: 13 | M13: 15 | AD13: فري لانسر | AE13: خالد عباس | AF13: يعمل | AH13: =IF(B13="","",INDEX(التقرير!$P$31:$P$260,ROW()-4)) -> حقق
A14: 2567991936 | B14: SABUJ SK | C14: كيتا | D14: =IF(B14="","",ROW()-4) -> 10 | E14: خطاب | F14: 45412 | I14: =IF(B14="","",J14+SUM(L14:AA14)+N(AC14)) -> 393 | J14: 339 | K14: 30 | L14: 28 | M14: 26 | AD14: كفالة | AE14: محمود خطاب | AF14: يعمل | AH14: =IF(B14="","",INDEX(التقرير!$P$31:$P$260,ROW()-4)) -> حقق
A15: 2585711043 | B15: هريدوى تشاندرا | C15: كيتا | D15: =IF(B15="","",ROW()-4) -> 11 | E15: خالد | F15: 46204 | I15: =IF(B15="","",J15+SUM(L15:AA15)+N(AC15)) -> 383 | J15: 339 | K15: 29 | L15: 27 | M15: 17 | AD15: فري لانسر | AE15: خالد عباس | AF15: يعمل | AH15: =IF(B15="","",INDEX(التقرير!$P$31:$P$260,ROW()-4)) -> حقق
A16: 2569644962 | B16: KHAYRUL ISLAM | C16: كيتا | D16: =IF(B16="","",ROW()-4) -> 12 | E16: خطاب | F16: 46139 | I16: =IF(B16="","",J16+SUM(L16:AA16)+N(AC16)) -> 342 | J16: 326 | K16: 26 | L16: 1 | M16: 15 | AD16: كفالة | AE16: محمود خطاب | AF16: يعمل | AH16: =IF(B16="","",INDEX(التقرير!$P$31:$P$260,ROW()-4)) -> حقق
... A34: 2558231755 | B34: محمد عزت سالم | C34: كيتا | D34: =IF(B34="","",ROW()-4) -> 30 | E34: خالد | F34: 46282 | I34: =IF(B34="","",J34+SUM(L34:AA34)+N(AC34)) -> 340 | J34: 300 | K34: 22 | L34: 23 | M34: 17 | AD34: فري لانسر | AE34: خالد عباس | AF34: يعمل | AH34: =IF(B34="","",INDEX(التقرير!$P$31:$P$260,ROW()-4)) -> حقق
A35: 2580251441 | B35: احمد مصطفي محمد | C35: كيتا | D35: =IF(B35="","",ROW()-4) -> 31 | E35: خالد | F35: 46295 | H35: اسناد ضعيف | I35: =IF(B35="","",J35+SUM(L35:AA35)+N(AC35)) -> 318 | J35: 281 | K35: 27 | L35: 24 | M35: 13 | AD35: فري لانسر | AE35: خالد عباس | AF35: يعمل | AH35: =IF(B35="","",INDEX(التقرير!$P$31:$P$260,ROW()-4)) -> حقق
A36: 2588109203 | B36: MAHMUDUL HASSAN | C36: كيتا | D36: =IF(B36="","",ROW()-4) -> 32 | E36: خالد | F36: 46204 | I36: =IF(B36="","",J36+SUM(L36:AA36)+N(AC36)) -> 321 | J36: 280 | K36: 19 | L36: 25 | M36: 16 | AD36: فري لانسر | AE36: خالد عباس | AF36: يعمل | AH36: =IF(B36="","",INDEX(التقرير!$P$31:$P$260,ROW()-4)) -> حقق
A37: 2586867323 | B37: JAHANGIR aLAM | C37: كيتا | D37: =IF(B37="","",ROW()-4) -> 33 | E37: خطاب | F37: 46079 | I37: =IF(B37="","",J37+SUM(L37:AA37)+N(AC37)) -> 322 | J37: 277 | K37: 8 | L37: 19 | M37: 26 | AD37: كفالة | AE37: محمود خطاب | AF37: يعمل | AH37: =IF(B37="","",INDEX(التقرير!$P$31:$P$260,ROW()-4)) -> حقق
A38: 2591331687 | B38: اسلام محمود السيد | C38: كيتا | D38: =IF(B38="","",ROW()-4) -> 34 | E38: خالد | F38: 46262 | I38: =IF(B38="","",J38+SUM(L38:AA38)+N(AC38)) -> 322 | J38: 277 | K38: 24 | L38: 28 | M38: 17 | AD38: فري لانسر | AE38: خالد عباس | AF38: يعمل | AH38: =IF(B38="","",INDEX(التقرير!$P$31:$P$260,ROW()-4)) -> حقق
A39: 2598450894 | B39: محمد شاه بران | C39: كيتا | D39: =IF(B39="","",ROW()-4) -> 35 | E39: خالد | F39: 46282 | I39: =IF(B39="","",J39+SUM(L39:AA39)+N(AC39)) -> 311 | J39: 275 | K39: 20 | L39: 17 | M39: 19 | AD39: فري لانسر | AE39: خالد عباس | AF39: يعمل | AH39: =IF(B39="","",INDEX(التقرير!$P$31:$P$260,ROW()-4)) -> حقق
A40: 2576049361 | B40: مد رقيب الاسلام | C40: كيتا | D40: =IF(B40="","",ROW()-4) -> 36 | E40: خالد | F40: 46272 | I40: =IF(B40="","",J40+SUM(L40:AA40)+N(AC40)) -> 321 | J40: 272 | K40: 17 | L40: 27 | M40: 22 | AD40: فري لانسر | AE40: خالد عباس | AF40: يعمل | AH40: =IF(B40="","",INDEX(التقرير!$P$31:$P$260,ROW()-4)) -> حقق
A41: 2590036691 | B41: عبدالحميد جمال شعبان | C41: كيتا | D41: =IF(B41="","",ROW()-4) -> 37 | E41: خالد | F41: 46241 | H41: مشكلة في نت المندوب وتم حلها | I41: =IF(B41="","",J41+SUM(L41:AA41)+N(AC41)) -> 304 | J41: 271 | K41: 18 | L41: 20 | M41: 13 | AD41: فري لانسر | AE41: خالد عباس | AF41: يعمل | AH41: =IF(B41="","",INDEX(التقرير!$P$31:$P$260,ROW()-4)) -> حقق
A42: 2589063623 | B42: MD Sajid AHMED | C42: كيتا | D42: =IF(B42="","",ROW()-4) -> 38 | E42: خالد | F42: 46204 | I42: =IF(B42="","",J42+SUM(L42:AA42)+N(AC42)) -> 312 | J42: 271 | K42: 21 | L42: 20 | M42: 21 | AD42: فري لانسر | AE42: خالد عباس | AF42: يعمل | AH42: =IF(B42="","",INDEX(التقرير!$P$31:$P$260,ROW()-4)) -> حقق
A43: 2585782051 | B43: HASAN AHMADE MOUSTAF | C43: كيتا | D43: =IF(B43="","",ROW()-4) -> 39 | E43: خطاب | F43: 45889 | I43: =IF(B43="","",J43+SUM(L43:AA43)+N(AC43)) -> 304 | J43: 268 | K43: 20 | L43: 21 | M43: 15 | AD43: كفالة | AE43: محمود خطاب | AF43: يعمل | AH43: =IF(B43="","",INDEX(التقرير!$P$31:$P$260,ROW()-4)) -> حقق
A44: 2579771524 | B44: MOHAMMED ABDALLHA | C44: كيتا | D44: =IF(B44="","",ROW()-4) -> 40 | E44: خطاب | F44: 46077 | H44: جاري توجية المندوب وتم انذارو | I44: =IF(B44="","",J44+SUM(L44:AA44)+N(AC44)) -> 288 | J44: 264 | K44: 26 | L44: 13 | M44: 11 | AD44: كفالة | AE44: محمود خطاب | AF44: يعمل | AH44: =IF(B44="","",INDEX(التقرير!$P$31:$P$260,ROW()-4)) -> حقق
A45: 2568200659 | B45: محمد ذاك حسين | C45: كيتا | D45: =IF(B45="","",ROW()-4) -> 41 | E45: خالد | F45: 46250 | I45: =IF(B45="","",J45+SUM(L45:AA45)+N(AC45)) -> 294 | J45: 259 | K45: 20 | L45: 20 | M45: 15 | AD45: فري لانسر | AE45: خالد عباس | AF45: يعمل | AH45: =IF(B45="","",INDEX(التقرير!$P$31:$P$260,ROW()-4)) -> حقق
A46: 2607927049 | B46: MEHEDI HASAN SABBIR | C46: كيتا | D46: =IF(B46="","",ROW()-4) -> 42 | E46: خالد | F46: 46293 | I46: =IF(B46="","",J46+SUM(L46:AA46)+N(AC46)) -> 275 | J46: 259 | K46: 15 | L46: 0 | M46: 16 | AD46: فري لانسر | AE46: خالد عباس | AF46: يعمل | AH46: =IF(B46="","",INDEX(التقرير!$P$31:$P$260,ROW()-4)) -> حقق
A47: 2609179607 | B47: احمد محمود أحمد زيدان | C47: كيتا | D47: =IF(B47="","",ROW()-4) -> 43 | E47: خالد | F47: 46204 | I47: =IF(B47="","",J47+SUM(L47:AA47)+N(AC47)) -> 300 | J47: 257 | K47: 23 | L47: 21 | M47: 22 | AD47: فري لانسر | AE47: خالد عباس | AF47: يعمل | AH47: =IF(B47="","",INDEX(التقرير!$P$31:$P$260,ROW()-4)) -> حقق
A48: 2586502839 | B48: صلاح الدين | C48: كيتا | D48: =IF(B48="","",ROW()-4) -> 44 | E48: خالد | F48: 46204 | I48: =IF(B48="","",J48+SUM(L48:AA48)+N(AC48)) -> 298 | J48: 256 | K48: 19 | L48: 25 | M48: 17 | AD48: فري لانسر | AE48: خالد عباس | AF48: يعمل | AH48: =IF(B48="","",INDEX(التقرير!$P$31:$P$260,ROW()-4)) -> حقق
A49: 2553949062 | B49: محمد أحمد فوزى أبوعجور | C49: كيتا | D49: =IF(B49="","",ROW()-4) -> 45 | E49: خطاب | F49: 45316 | I49: =IF(B49="","",J49+SUM(L49:AA49)+N(AC49)) -> 286 | J49: 249 | K49: 20 | L49: 21 | M49: 16 | AD49: كفالة | AE49: محمود خطاب | AF49: يعمل | AH49: =IF(B49="","",INDEX(التقرير!$P$31:$P$260,ROW()-4)) -> حقق
A50: 2557509482 | B50: MAHMOUDE ABO GARARA | C50: كيتا | D50: =IF(B50="","",ROW()-4) -> 46 | E50: خطاب | F50: 45322 | I50: =IF(B50="","",J50+SUM(L50:AA50)+N(AC50)) -> 288 | J50: 247 | K50: 24 | L50: 22 | M50: 19 | AD50: كفالة | AE50: محمود خطاب | AF50: يعمل | AH50: =IF(B50="","",INDEX(التقرير!$P$31:$P$260,ROW()-4)) -> حقق
A51: 2568883777 | B51: Jahidul Islam | C51: كيتا | D51: =IF(B51="","",ROW()-4) -> 47 | E51: خالد | F51: 46204 | I51: =IF(B51="","",J51+SUM(L51:AA51)+N(AC51)) -> 283 | J51: 245 | K51: 18 | L51: 19 | M51: 19 | AD51: فري لانسر | AE51: خالد عباس | AF51: يعمل | AH51: =IF(B51="","",INDEX(التقرير!$P$31:$P$260,ROW()-4)) -> حقق
A52: 2562201455 | B52: TANVEER SHAFI | C52: كيتا | D52: =IF(B52="","",ROW()-4) -> 48 | E52: خطاب | F52: 45351 | I52: =IF(B52="","",J52+SUM(L52:AA52)+N(AC52)) -> 278 | J52: 244 | K52: 15 | L52: 15 | M52: 19 | AD52: كفالة | AE52: محمود خطاب | AF52: يعمل | AH52: =IF(B52="","",INDEX(التقرير!$P$31:$P$260,ROW()-4)) -> حقق
A53: 2600845370 | B53: معين الدين رنا | C53: كيتا | D53: =IF(B53="","",ROW()-4) -> 49 | E53: خالد | F53: 46204 | I53: =IF(B53="","",J53+SUM(L53:AA53)+N(AC53)) -> 284 | J53: 243 | K53: 18 | L53: 20 | M53: 21 | AD53: فري لانسر | AE53: خالد عباس | AF53: يعمل | AH53: =IF(B53="","",INDEX(التقرير!$P$31:$P$260,ROW()-4)) -> حقق
A54: 2600468512 | B54: Rayhan Ahmed Ahmed | C54: كيتا | D54: =IF(B54="","",ROW()-4) -> 50 | E54: خالد | F54: 46204 | I54: =IF(B54="","",J54+SUM(L54:AA54)+N(AC54)) -> 287 | J54: 241 | K54: 16 | L54: 24 | M54: 22 | AD54: فري لانسر | AE54: خالد عباس | AF54: يعمل | AH54: =IF(B54="","",INDEX(التقرير!$P$31:$P$260,ROW()-4)) -> حقق
A55: 2613704226 | B55: mohammed anuar mia | C55: كيتا | D55: =IF(B55="","",ROW()-4) -> 51 | E55: خالد | F55: 46204 | H55: أسناد ضعيف | I55: =IF(B55="","",J55+SUM(L55:AA55)+N(AC55)) -> 266 | J55: 240 | K55: 12 | L55: 17 | M55: 9 | AD55: فري لانسر | AE55: خالد عباس | AF55: يعمل | AH55: =IF(B55="","",INDEX(التقرير!$P$31:$P$260,ROW()-4)) -> حقق
A56: 2571010418 | B56: MD SHRABON | C56: كيتا | D56: =IF(B56="","",ROW()-4) -> 52 | E56: خالد | F56: 46293 | I56: =IF(B56="","",J56+SUM(L56:AA56)+N(AC56)) -> 284 | J56: 237 | K56: 19 | L56: 27 | M56: 20 | AD56: فري لانسر | AE56: خالد عباس | AF56: يعمل | AH56: =IF(B56="","",INDEX(التقرير!$P$31:$P$260,ROW()-4)) -> حقق
A57: 2585069020 | B57: محمد مهدي حسن | C57: كيتا | D57: =IF(B57="","",ROW()-4) -> 53 | E57: خالد | F57: 46294 | I57: =IF(B57="","",J57+SUM(L57:AA57)+N(AC57)) -> 277 | J57: 237 | K57: 19 | L57: 26 | M57: 14 | AD57: فري لانسر | AE57: خالد عباس | AF57: يعمل | AH57: =IF(B57="","",INDEX(التقرير!$P$31:$P$260,ROW()-4)) -> حقق
...

Sheet الإعدادات
A1: إعدادات التقييم
A2: تاريخ التقرير (بيتحدّث لوحده لآخر يوم فيه إدخال) | B2: =MAX(B10,SUMPRODUCT(MAX(('الإدخال اليومي'!$L$4:$AA$4>0)*'الإدخال اليومي'!$L$3:$AA$3))) -> 46312
A3: هدف الشهر (طلب) | B3: 450
A4: أيام الشهر | B4: 30
A5: الهدف اليومي (طلب) | B5: =B3/B4 -> 15
A6: الأيام المنقضية | B6: =DAY(B2) -> 17
A7: الهدف حتى تاريخ التقرير | B7: =B5*B6 -> 255
A8: حد "قريب" (نسبة من الهدف) | B8: 0.8
A9: بداية الشهر | B9: =DATE(YEAR(B2),MONTH(B2),1) -> 46296
A10: تاريخ آخر رصيد (الإجمالي الأساسي) | B10: 46310
A12: طريقة التقييم: هدف كل مندوب = 15 طلب × أيام احتسابه (من أول الشهر أو من تاريخ بدايته، ناقص أيام الغياب بعذر). حقق = إجمالي الطلبات ≥ هدفه. قريب = ≥ 80% من هدفه. بعيد = أقل. "ترك العمل" بيتستبعد.
A17: الهدف الشهري حسب المشروع
A18: المشروع | B18: الهدف الشهري
A19: هنجرستيشن | B19: 450
A20: كيتا | B20: 450
A21: نينجا | B21: 360
A22: امازون
A23: امازون: مفيش تارجت طلبات، بيتسجل عدد الشحنات بس. مشروع مش في الجدول بياخد الهدف العام (B3).
